Workbook

Sheet Resumen
A1: Rutas activas con km inconsistente — SIT EBEMA
A2: Criterio: km cargado < 90% de la distancia en línea recta entre el centro de origen y la comuna (sólo si la línea recta > 30 km). Fuente: tabla routes y logistics_centres de Producción, 27-09-2026.
A4: Factor carretera / línea recta | B4: 1.25 | C4: Supuesto para el "KM estimado" de referencia (la distancia por carretera suele ser 1,2–1,35 × la línea recta). Ajustable.
A6: Diagnóstico | B6: Rutas | C6: Qué significa
A7: 1. KM EN CERO | B7: =COUNTIF('Rutas con distorsión'!$K$2:$K$218,A7) -> 10 | C7: La ruta no tiene km cargados (incluye destinos especiales como Isla de Pascua o Antártica).
A8: 2. KM COPIADO DE SANTIAGO | B8: =COUNTIF('Rutas con distorsión'!$K$2:$K$218,A8) -> 132 | C8: El km es igual (±2) al de la ruta desde Santiago al mismo destino: se copió la distancia medida desde Santiago.
A9: 3. KM MUY BAJO | B9: =COUNTIF('Rutas con distorsión'!$K$2:$K$218,A9) -> 50 | C9: El km es menor a la mitad de la línea recta: error de carga.
A10: 4. LEVE (revisar coordenada) | B10: =COUNTIF('Rutas con distorsión'!$K$2:$K$218,A10) -> 25 | C10: Diferencia menor; suele ser la coordenada de la comuna (centroide lejos del centro urbano). Revisar antes de cambiar el km.
A11: Total | B11: =SUM(B7:B10) -> 217
A13: Por centro de origen
A14: Centro | B14: Rutas
A15: CD Antofagasta | B15: =COUNTIF('Rutas con distorsión'!$B$2:$B$218,A15) -> 20
A16: CD Chillan | B16: =COUNTIF('Rutas con distorsión'!$B$2:$B$218,A16) -> 39
A17: CD Concepción | B17: =COUNTIF('Rutas con distorsión'!$B$2:$B$218,A17) -> 68
A18: CD Coquimbo | B18: =COUNTIF('Rutas con distorsión'!$B$2:$B$218,A18) -> 27
A19: CD La Calera | B19: =COUNTIF('Rutas con distorsión'!$B$2:$B$218,A19) -> 12
A20: CD Puerto Montt | B20: =COUNTIF('Rutas con distorsión'!$B$2:$B$218,A20) -> 5
A21: CD Rancagua | B21: =COUNTIF('Rutas con distorsión'!$B$2:$B$218,A21) -> 18
A22: CD San Bernado | B22: =COUNTIF('Rutas con distorsión'!$B$2:$B$218,A22) -> 5
A23: CD Talca | B23: =COUNTIF('Rutas con distorsión'!$B$2:$B$218,A23) -> 14
A24: CD Temuco | B24: =COUNTIF('Rutas con distorsión'!$B$2:$B$218,A24) -> 8
A25: Planta Electrosoldado | B25: =COUNTIF('Rutas con distorsión'!$B$2:$B$218,A25) -> 1

Sheet Rutas con distorsión
A1: Código ruta | B1: Centro origen | C1: Id centro | D1: Destino | E1: Región | F1: Clasificación | G1: KM cargado | H1: KM línea recta | I1: % KM / línea recta | J1: KM estimado (referencia) | K1: Diagnóstico | L1: KM ruta desde Santiago (mismo destino) | M1: Lat destino | N1: Lon destino | O1: KM por carretera (OSRM) | P1: KM corregido (completar) | Q1: Observación
A2: COQ76 | B2: CD Coquimbo | C2: 1040 | D2: JUAN FERNANDEZ | E2: Valparaíso | F2: Interregional | G2: 0 | H2: 794 | I2: =IF(H2=0,"",G2/H2) -> 0 | J2: =ROUND(H2*Resumen!$B$4,0) -> 993 | K2: 1. KM EN CERO | M2: -33.64445 | N2: -78.826224 | O2: 799 | Q2: No se propone cambio: isla / diferencia leve (revisar coordenada) / sin ruta terrestre
A3: COQ80 | B3: CD Coquimbo | C3: 1040 | D3: ISLA DE PASCUA | E3: Valparaíso | F3: Interregional | G3: 0 | H3: 3719 | I3: =IF(H3=0,"",G3/H3) -> 0 | J3: =ROUND(H3*Resumen!$B$4,0) -> 4649 | K3: 1. KM EN CERO | M3: -27.125932 | N3: -109.34959 | Q3: No se propone cambio: isla / diferencia leve (revisar coordenada) / sin ruta terrestre
A4: LAC622 | B4: CD La Calera | C4: 1050 | D4: JUAN FERNANDEZ | E4: Valparaíso | F4: Regional | G4: 0 | H4: 716 | I4: =IF(H4=0,"",G4/H4) -> 0 | J4: =ROUND(H4*Resumen!$B$4,0) -> 895 | K4: 1. KM EN CERO | M4: -33.64445 | N4: -78.826224 | O4: 506 | Q4: No se propone cambio: isla / diferencia leve (revisar coordenada) / sin ruta terrestre
A5: LAC624 | B5: CD La Calera | C5: 1050 | D5: ISLA DE PASCUA | E5: Valparaíso | F5: Regional | G5: 0 | H5: 3709 | I5: =IF(H5=0,"",G5/H5) -> 0 | J5: =ROUND(H5*Resumen!$B$4,0) -> 4636 | K5: 1. KM EN CERO | M5: -27.125932 | N5: -109.34959 | Q5: No se propone cambio: isla / diferencia leve (revisar coordenada) / sin ruta terrestre
A6: PMO725 | B6: CD Puerto Montt | C6: 1100 | D6: ANTARTICA | E6: Magallanes y de la Antártica Chilena | F6: Interregional | G6: 0 | H6: 1554 | I6: =IF(H6=0,"",G6/H6) -> 0 | J6: =ROUND(H6*Resumen!$B$4,0) -> 1943 | K6: 1. KM EN CERO | M6: -55.175083 | N6: -68.658921 | O6: 2655 | Q6: No se propone cambio: isla / diferencia leve (revisar coordenada) / sin ruta terrestre
A7: RAN686 | B7: CD Rancagua | C7: 1060 | D7: PEAJE ANGOSTURA | E7: Metropolitana de Santiago | F7: Interregional | G7: 0 | H7: 31 | I7: =IF(H7=0,"",G7/H7) -> 0 | J7: =ROUND(H7*Resumen!$B$4,0) -> 39 | K7: 1. KM EN CERO | M7: -33.907615 | N7: -70.731267 | O7: 40 | P7: 40 | Q7: Propuesto: usar km por carretera
A8: RAN692 | B8: CD Rancagua | C8: 1060 | D8: JUAN FERNANDEZ | E8: Valparaíso | F8: Interregional | G8: 0 | H8: 748 | I8: =IF(H8=0,"",G8/H8) -> 0 | J8: =ROUND(H8*Resumen!$B$4,0) -> 935 | K8: 1. KM EN CERO | M8: -33.64445 | N8: -78.826224 | O8: 308 | Q8: No se propone cambio: isla / diferencia leve (revisar coordenada) / sin ruta terrestre
A9: RAN696 | B9: CD Rancagua | C9: 1060 | D9: ISLA DE PASCUA | E9: Valparaíso | F9: Interregional | G9: 0 | H9: 3752 | I9: =IF(H9=0,"",G9/H9) -> 0 | J9: =ROUND(H9*Resumen!$B$4,0) -> 4690 | K9: 1. KM EN CERO | M9: -27.125932 | N9: -109.34959 | Q9: No se propone cambio: isla / diferencia leve (revisar coordenada) / sin ruta terrestre
A10: TAL648 | B10: CD Talca | C10: 1070 | D10: JUAN FERNANDEZ | E10: Valparaíso | F10: Interregional | G10: 0 | H10: 688 | I10: =IF(H10=0,"",G10/H10) -> 0 | J10: =ROUND(H10*Resumen!$B$4,0) -> 860 | K10: 1. KM EN CERO | M10: -33.64445 | N10: -78.826224 | O10: 138 | Q10: No se propone cambio: isla / diferencia leve (revisar coordenada) / sin ruta terrestre
A11: TAL652 | B11: CD Talca | C11: 1070 | D11: ISLA DE PASCUA | E11: Valparaíso | F11: Interregional | G11: 0 | H11: 3676 | I11: =IF(H11=0,"",G11/H11) -> 0 | J11: =ROUND(H11*Resumen!$B$4,0) -> 4595 | K11: 1. KM EN CERO | M11: -27.125932 | N11: -109.34959 | Q11: No se propone cambio: isla / diferencia leve (revisar coordenada) / sin ruta terrestre
A12: ANT557 | B12: CD Antofagasta | C12: 1020 | D12: CALERA | E12: Valparaíso | F12: Interregional | G12: 104 | H12: 1027 | I12: =IF(H12=0,"",G12/H12) -> 0.10126582 | J12: =ROUND(H12*Resumen!$B$4,0) -> 1284 | K12: 2. KM COPIADO DE SANTIAGO | L12: 103 | M12: -32.787129 | N12: -71.185777 | O12: 1231 | P12: 1231 | Q12: Propuesto: usar km por carretera
A13: ANT575 | B13: CD Antofagasta | C13: 1020 | D13: ILLAPEL | E13: Coquimbo | F13: Interregional | G13: 273 | H13: 899 | I13: =IF(H13=0,"",G13/H13) -> 0.30367075 | J13: =ROUND(H13*Resumen!$B$4,0) -> 1124 | K13: 2. KM COPIADO DE SANTIAGO | L13: 272 | M13: -31.63537 | N13: -71.168878 | O13: 1126 | P13: 1126 | Q13: Propuesto: usar km por carretera
A14: ANT578 | B14: CD Antofagasta | C14: 1020 | D14: SALAMANCA | E14: Coquimbo | F14: Interregional | G14: 290 | H14: 913 | I14: =IF(H14=0,"",G14/H14) -> 0.31763417 | J14: =ROUND(H14*Resumen!$B$4,0) -> 1141 | K14: 2. KM COPIADO DE SANTIAGO | L14: 289 | M14: -31.773906 | N14: -70.960106 | O14: 1159 | P14: 1159 | Q14: Propuesto: usar km por carretera
A15: ANT587 | B15: CD Antofagasta | C15: 1020 | D15: EL BOSQUE | E15: Metropolitana de Santiago | F15: Interregional | G15: 30 | H15: 1109 | I15: =IF(H15=0,"",G15/H15) -> 0.027051398 | J15: =ROUND(H15*Resumen!$B$4,0) -> 1386 | K15: 2. KM COPIADO DE SANTIAGO | L15: 28 | M15: -33.546572 | N15: -70.666752 | O15: 1353 | P15: 1353 | Q15: Propuesto: usar km por carretera
A16: ANT588 | B16: CD Antofagasta | C16: 1020 | D16: ESTACION CENTRAL | E16: Metropolitana de Santiago | F16: Interregional | G16: 14 | H16: 1098 | I16: =IF(H16=0,"",G16/H16) -> 0.012750455 | J16: =ROUND(H16*Resumen!$B$4,0) -> 1373 | K16: 2. KM COPIADO DE SANTIAGO | L16: 15 | M16: -33.452225 | N16: -70.679051 | O16: 1341 | P16: 1341 | Q16: Propuesto: usar km por carretera
A17: ANT590 | B17: CD Antofagasta | C17: 1020 | D17: INDEPENDENCIA | E17: Metropolitana de Santiago | F17: Interregional | G17: 12 | H17: 1095 | I17: =IF(H17=0,"",G17/H17) -> 0.010958904 | J17: =ROUND(H17*Resumen!$B$4,0) -> 1369 | K17: 2. KM COPIADO DE SANTIAGO | L17: 11 | M17: -33.419565 | N17: -70.669614 | O17: 1336 | P17: 1336 | Q17: Propuesto: usar km por carretera
A18: ANT591 | B18: CD Antofagasta | C18: 1020 | D18: LA CISTERNA | E18: Metropolitana de Santiago | F18: Interregional | G18: 24 | H18: 1108 | I18: =IF(H18=0,"",G18/H18) -> 0.02166065 | J18: =ROUND(H18*Resumen!$B$4,0) -> 1385 | K18: 2. KM COPIADO DE SANTIAGO | L18: 26 | M18: -33.53735 | N18: -70.664333 | O18: 1352 | P18: 1352 | Q18: Propuesto: usar km por carretera
A19: ANT594 | B19: CD Antofagasta | C19: 1020 | D19: LA PINTANA | E19: Metropolitana de Santiago | F19: Interregional | G19: 34 | H19: 1112 | I19: =IF(H19=0,"",G19/H19) -> 0.03057554 | J19: =ROUND(H19*Resumen!$B$4,0) -> 1390 | K19: 2. KM COPIADO DE SANTIAGO | L19: 33 | M19: -33.574613 | N19: -70.632129 | O19: 1358 | P19: 1358 | Q19: Propuesto: usar km por carretera
A20: ANT599 | B20: CD Antofagasta | C20: 1020 | D20: LO PRADO | E20: Metropolitana de Santiago | F20: Interregional | G20: 15 | H20: 1097 | I20: =IF(H20=0,"",G20/H20) -> 0.013673655 | J20: =ROUND(H20*Resumen!$B$4,0) -> 1371 | K20: 2. KM COPIADO DE SANTIAGO | L20: 17 | M20: -33.443409 | N20: -70.716753 | O20: 1340 | P20: 1340 | Q20: Propuesto: usar km por carretera
A21: ANT600 | B21: CD Antofagasta | C21: 1020 | D21: MACUL | E21: Metropolitana de Santiago | F21: Interregional | G21: 25 | H21: 1104 | I21: =IF(H21=0,"",G21/H21) -> 0.022644928 | J21: =ROUND(H21*Resumen!$B$4,0) -> 1380 | K21: 2. KM COPIADO DE SANTIAGO | L21: 25 | M21: -33.509238 | N21: -70.590047 | O21: 1355 | P21: 1355 | Q21: Propuesto: usar km por carretera
A22: ANT601 | B22: CD Antofagasta | C22: 1020 | D22: MAIPU | E22: Metropolitana de Santiago | F22: Interregional | G22: 26 | H22: 1105 | I22: =IF(H22=0,"",G22/H22) -> 0.023529412 | J22: =ROUND(H22*Resumen!$B$4,0) -> 1381 | K22: 2. KM COPIADO DE SANTIAGO | L22: 26 | M22: -33.509933 | N22: -70.757309 | O22: 1352 | P22: 1352 | Q22: Propuesto: usar km por carretera
A23: ANT622 | B23: CD Antofagasta | C23: 1020 | D23: BUIN | E23: Metropolitana de Santiago | F23: Interregional | G23: 47 | H23: 1129 | I23: =IF(H23=0,"",G23/H23) -> 0.041629761 | J23: =ROUND(H23*Resumen!$B$4,0) -> 1411 | K23: 2. KM COPIADO DE SANTIAGO | L23: 47 | M23: -33.732365 | N23: -70.728433 | O23: 1372 | P23: 1372 | Q23: Propuesto: usar km por carretera
... A147: ANT598 | B147: CD Antofagasta | C147: 1020 | D147: LO ESPEJO | E147: Metropolitana de Santiago | F147: Interregional | G147: 28 | H147: 1105 | I147: =IF(H147=0,"",G147/H147) -> 0.025339367 | J147: =ROUND(H147*Resumen!$B$4,0) -> 1381 | K147: 3. KM MUY BAJO | L147: 24 | M147: -33.514527 | N147: -70.685882 | O147: 1350 | P147: 1350 | Q147: Propuesto: usar km por carretera
A148: CHI100 | B148: CD Chillan | C148: 1160 | D148: MARÍA PINTO | E148: Metropolitana de Santiago | F148: Interregional | G148: 56 | H148: 358 | I148: =IF(H148=0,"",G148/H148) -> 0.15642458 | J148: =ROUND(H148*Resumen!$B$4,0) -> 448 | K148: 3. KM MUY BAJO | M148: -33.51353 | N148: -71.097867 | O148: 450 | P148: 450 | Q148: Propuesto: usar km por carretera
A149: CHI103 | B149: CD Chillan | C149: 1160 | D149: EL MONTE | E149: Metropolitana de Santiago | F149: Interregional | G149: 68 | H149: 343 | I149: =IF(H149=0,"",G149/H149) -> 0.19825073 | J149: =ROUND(H149*Resumen!$B$4,0) -> 429 | K149: 3. KM MUY BAJO | L149: 60 | M149: -33.678319 | N149: -70.978246 | O149: 397 | P149: 397 | Q149: Propuesto: usar km por carretera
A150: CHI104 | B150: CD Chillan | C150: 1160 | D150: ISLA DE MAIPO | E150: Metropolitana de Santiago | F150: Interregional | G150: 59 | H150: 338 | I150: =IF(H150=0,"",G150/H150) -> 0.17455621 | J150: =ROUND(H150*Resumen!$B$4,0) -> 423 | K150: 3. KM MUY BAJO | L150: 63 | M150: -33.749685 | N150: -70.900751 | O150: 381 | P150: 381 | Q150: Propuesto: usar km por carretera
A151: CHI155 | B151: CD Chillan | C151: 1160 | D151: ROMERAL | E151: Valparaíso | F151: Interregional | G151: 206 | H151: 434 | I151: =IF(H151=0,"",G151/H151) -> 0.47465438 | J151: =ROUND(H151*Resumen!$B$4,0) -> 543 | K151: 3. KM MUY BAJO | L151: 201 | M151: -32.825059 | N151: -71.02159 | O151: 497 | P151: 497 | Q151: Propuesto: usar km por carretera
A152: CHI64 | B152: CD Chillan | C152: 1160 | D152: LA FLORIDA | E152: Metropolitana de Santiago | F152: Interregional | G152: 27 | H152: 370 | I152: =IF(H152=0,"",G152/H152) -> 0.072972973 | J152: =ROUND(H152*Resumen!$B$4,0) -> 463 | K152: 3. KM MUY BAJO | L152: 35 | M152: -33.541615 | N152: -70.571212 | O152: 404 | P152: 404 | Q152: Propuesto: usar km por carretera
A153: CHI68 | B153: CD Chillan | C153: 1160 | D153: LAS CONDES | E153: Metropolitana de Santiago | F153: Interregional | G153: 17 | H153: 384 | I153: =IF(H153=0,"",G153/H153) -> 0.044270833 | J153: =ROUND(H153*Resumen!$B$4,0) -> 480 | K153: 3. KM MUY BAJO | L153: 25 | M153: -33.405487 | N153: -70.574383 | O153: 416 | P153: 416 | Q153: Propuesto: usar km por carretera
A154: CHI69 | B154: CD Chillan | C154: 1160 | D154: LO BARNECHEA | E154: Metropolitana de Santiago | F154: Interregional | G154: 23 | H154: 392 | I154: =IF(H154=0,"",G154/H154) -> 0.058673469 | J154: =ROUND(H154*Resumen!$B$4,0) -> 490 | K154: 3. KM MUY BAJO | L154: 37 | M154: -33.352834 | N154: -70.518564 | O154: 427 | P154: 427 | Q154: Propuesto: usar km por carretera
A155: CHI70 | B155: CD Chillan | C155: 1160 | D155: LO ESPEJO | E155: Metropolitana de Santiago | F155: Interregional | G155: 28 | H155: 369 | I155: =IF(H155=0,"",G155/H155) -> 0.075880759 | J155: =ROUND(H155*Resumen!$B$4,0) -> 461 | K155: 3. KM MUY BAJO | L155: 24 | M155: -33.514527 | N155: -70.685882 | O155: 398 | P155: 398 | Q155: Propuesto: usar km por carretera
A156: CHI76 | B156: CD Chillan | C156: 1160 | D156: PEÑALOLÉN | E156: Metropolitana de Santiago | F156: Interregional | G156: 25 | H156: 378 | I156: =IF(H156=0,"",G156/H156) -> 0.066137566 | J156: =ROUND(H156*Resumen!$B$4,0) -> 473 | K156: 3. KM MUY BAJO | L156: 41 | M156: -33.488416 | N156: -70.509435 | O156: 416 | P156: 416 | Q156: Propuesto: usar km por carretera
A157: CON660 | B157: CD Concepción | C157: 1080 | D157: LOS VILOS | E157: Coquimbo | F157: Interregional | G157: 215 | H157: 543 | I157: =IF(H157=0,"",G157/H157) -> 0.39594843 | J157: =ROUND(H157*Resumen!$B$4,0) -> 679 | K157: 3. KM MUY BAJO | L157: 188 | M157: -32.121361 | N157: -71.502913 | O157: 696 | P157: 696 | Q157: Propuesto: usar km por carretera
A158: CON668 | B158: CD Concepción | C158: 1080 | D158: CASABLANCA | E158: Valparaíso | F158: Interregional | G158: 79 | H158: 416 | I158: =IF(H158=0,"",G158/H158) -> 0.18990385 | J158: =ROUND(H158*Resumen!$B$4,0) -> 520 | K158: 3. KM MUY BAJO | L158: 82 | M158: -33.336518 | N158: -71.410551 | O158: 569 | P158: 569 | Q158: Propuesto: usar km por carretera
A159: CON669 | B159: CD Concepción | C159: 1080 | D159: CONCON | E159: Valparaíso | F159: Interregional | G159: 133 | H159: 455 | I159: =IF(H159=0,"",G159/H159) -> 0.29230769 | J159: =ROUND(H159*Resumen!$B$4,0) -> 569 | K159: 3. KM MUY BAJO | L159: 143 | M159: -32.949194 | N159: -71.47886 | O159: 622 | P159: 622 | Q159: Propuesto: usar km por carretera
A160: CON680 | B160: CD Concepción | C160: 1080 | D160: PAPUDO | E160: Valparaíso | F160: Interregional | G160: 159 | H160: 504 | I160: =IF(H160=0,"",G160/H160) -> 0.31547619 | J160: =ROUND(H160*Resumen!$B$4,0) -> 630 | K160: 3. KM MUY BAJO | L160: 156 | M160: -32.501554 | N160: -71.435857 | O160: 666 | P160: 666 | Q160: Propuesto: usar km por carretera
... A169: CON716 | B169: CD Concepción | C169: 1080 | D169: LO BARNECHEA | E169: Metropolitana de Santiago | F169: Interregional | G169: 23 | H169: 451 | I169: =IF(H169=0,"",G169/H169) -> 0.050997783 | J169: =ROUND(H169*Resumen!$B$4,0) -> 564 | K169: 3. KM MUY BAJO | L169: 37 | M169: -33.352834 | N169: -70.518564 | O169: 522 | P169: 522 | Q169: Propuesto: usar km por carretera
A170: CON747 | B170: CD Concepción | C170: 1080 | D170: MARÍA PINTO | E170: Metropolitana de Santiago | F170: Interregional | G170: 56 | H170: 410 | I170: =IF(H170=0,"",G170/H170) -> 0.13658537 | J170: =ROUND(H170*Resumen!$B$4,0) -> 513 | K170: 3. KM MUY BAJO | M170: -33.51353 | N170: -71.097867 | O170: 546 | P170: 546 | Q170: Propuesto: usar km por carretera
A171: CON750 | B171: CD Concepción | C171: 1080 | D171: EL MONTE | E171: Metropolitana de Santiago | F171: Interregional | G171: 68 | H171: 398 | I171: =IF(H171=0,"",G171/H171) -> 0.17085427 | J171: =ROUND(H171*Resumen!$B$4,0) -> 498 | K171: 3. KM MUY BAJO | L171: 60 | M171: -33.678319 | N171: -70.978246 | O171: 492 | P171: 492 | Q171: Propuesto: usar km por carretera
...
